Workbook
Name Type: #REF!

Sheet Summary
H1: 44326 | M1: 44327 | R1: 44328
A2: Executed Group | B2: Executed Topic | C2: BEV21 I20 2041.101 | H2: 2041.101
C3: Passed | D3: Fail | E3: Other | F3: Total Test cases | H3: Passed | I3: Fail | J3: Other | K3: Total Test cases | M3: Passed | N3: Fail | O3: Other | P3: Total Test cases | R3: Passed | S3: Fail | T3: Other | U3: Total Test cases
A4: FuSa (TSR) | B4: Charger
A5: FuSa (TSR) | B5: DCDC Main
A6: FuSa (TSR) | B6: DCDC EFAN
A7: FuSa (TSR) | B7: DCDC SEV
A8: FuSa (TSR) | B8: FaultInjection
A9: Total | H9: =SUM(H4:H8) | I9: =SUM(I4:I8) | J9: =SUM(J4:J8) | K9: =SUM(K4:K8) | M9: =SUM(M4:M8) | N9: =SUM(N4:N8) | O9: =SUM(O4:O8) | P9: =SUM(P4:P8) | R9: =SUM(R4:R8) | S9: =SUM(S4:S8) | T9: =SUM(T4:T8) | U9: =SUM(U4:U8)
H11: 44329 | M11: 44330 | R11: 44333 | W11: 44334
A12: Executed Group | B12: Executed Topic | C12: G26 2041.40 | H12: G26 2041.51 CRETA PV024 | M12: G26 2041.51 CRETA PV024 | R12: G26 2041.51 CRETA PV024 | W12: G26 2041.51 CRETA PV024
C13: Passed | D13: Fail | E13: Other | F13: Total Test cases | H13: Passed | I13: Fail | J13: Other | K13: Total Test cases | M13: Passed | N13: Fail | O13: Other | P13: Total Test cases | R13: Passed | S13: Fail | T13: Other | U13: Total Test cases | W13: Passed | X13: Fail | Y13: Other | Z13: Total Test cases
A14: Function | B14: 14DCDC | C14: 1222 | D14: 68 | E14: 0 | F14: 1290
A15: Function | B15: KLH | C15: 409 | D15: 10 | E15: 1 | F15: 419
A16: Total | C16: =SUM(C14:C15) | D16: =SUM(D14:D15) | E16: =SUM(E14:E15) | F16: =SUM(F14:F15) | H16: =SUM(H14,H15) | I16: =SUM(I14,I15) | J16: =SUM(J14,J15) | K16: =SUM(K14,K15) | M16: =SUM(M14,M15) | N16: =SUM(N14,N15) | O16: =SUM(O14,O15) | P16: =SUM(P14,P15) | R16: =SUM(R14,R15) | S16: =SUM(S14,S15) | T16: =SUM(T14,T15) | U16: =SUM(U14,U15) | W16: =SUM(W14,W15) | X16: =SUM(X14,X15) | Y16: =SUM(Y14,Y15) | Z16: =SUM(Z14,Z15)
A18: Overall Progress
A19: Task | B19: Engineer | C19: Status | D19: Reviewed by | E19: Note
A20: Flash SW
A21: Setup CANoe
A22: Setup automated execution
A23: Collect & Summarize test result | D23: -
A24: -Charger | D24: -
A25: -14DCDC | D25: -
A26: SEV
A27: EFAN
A28: Fault injection | D28: -
A29: Manual test | D29: -
A30: Debug fails | D30: -
A31: -Charger | D31: - | E31: 9 tc
A32: -14DCDC | D32: - | E32: 1 tc
A33: SEV | D33: - | E33: 0 tc
A34: EFAN | D34: - | E34: 0 tc
A35: FTT | E35: 1 tc
A36: -Fault injection | D36: -
A37: -Manual test | D37: -
A38: Fill final test report
A39: -Charger | D39: -
A40: -14DCDC | D40: -
A41: -FTT | D41: -
A45: Test Bench | B45: TB1 | C45: TB2 | D45: TB3 | E45: VT1 | F45: VT5
...

Sheet Setup Report 
A3: Test bench: Example | F3: Test bench: TB1 | K3: Test bench: TB2 | P3: Test bench: TB3 | U3: Test bench: VT1 | Z3: Test bench: VT5
A4: Date: 27 Apr 2021 | F4: Date | G4: 44323 | K4: Date | L4: 44323 | P4: Date | Q4: 44323 | U4: Date | V4: 44323 | Z4: Date | AB4: 44323
A5: Engineer: Buranon | F5: Engineer | G5: Non | K5: Engineer | P5: Engineer | U5: Engineer | Z5: Engineer
A6: Review by | F6: Review by | K6: Review by | P6: Review by | U6: Review by | Z6: Review by
A7: Reviewed date | F7: Reviewed date | K7: Reviewed date | P7: Reviewed date | Q7: 44323 | U7: Reviewed date | V7: 44323 | Z7: Reviewed date | AB7: 44323
A8: Check point | F8: Check point | K8: Check point | P8: Check point | U8: Check point | Z8: Check point
A9: No. | B9: Details | C9: Completed | D9: Reviewed | F9: No. | G9: Details | H9: Completed | I9: Reviewed | K9: No. | L9: Details | M9: Completed | N9: Reviewed | P9: No. | Q9: Details | R9: Completed | S9: Reviewed | U9: No. | V9: Details | W9: Completed | X9: Reviewed | Z9: No. | AA9: Details | AB9: Completed | AC9: Reviewed
A10: 1 | B10: SW+CRETA version panel | F10: 1 | G10: SW+CRETA version panel | K10: 1 | L10: SW+CRETA version panel | P10: 1 | Q10: SW+CRETA version panel | U10: 1 | V10: SW+CRETA version panel | Z10: 1 | AA10: SW+CRETA version panel
A11: 2 | B11: Setup CANoe -Correct .ARXML file -Correct .LDF file -Correct CAPL node | F11: 2 | G11: Setup CANoe -Correct .ARXML file -Correct .LDF file -Correct CAPL node | K11: 2 | L11: Setup CANoe -Correct .ARXML file -Correct .LDF file -Correct CAPL node | P11: 2 | Q11: Setup CANoe -Correct .ARXML file -Correct .LDF file -Correct CAPL node | U11: 2 | V11: Setup CANoe -Correct .ARXML file -Correct .LDF file -Correct CAPL node | Z11: 2 | AA11: Setup CANoe -Correct .ARXML file -Correct .LDF file -Correct CAPL node
A12: 3 | B12: ENG9_Start All Pass | F12: 3 | G12: ENG9_Start All Pass | K12: 3 | L12: ENG9_Start All Pass | P12: 3 | Q12: ENG9_Start All Pass | U12: 3 | V12: ENG9_Start All Pass | Z12: 3 | AA12: ENG9_Start All Pass
A13: 4 | B13: Setup automated execution -Clear log folder -Use original Select Group -Correct init file -Active tes units -Confirm 1 st result | C13: Yes | F13: 4 | G13: Setup automated execution -Clear log folder -Use original Select Group -Correct init file -Active tes units -Confirm 1 st result | K13: 4 | L13: Setup automated execution -Clear log folder -Use original Select Group -Correct init file -Active tes units -Confirm 1 st result | P13: 4 | Q13: Setup automated execution -Clear log folder -Use original Select Group -Correct init file -Active test units -Confirm 1 st result | U13: 4 | V13: Setup automated execution -Clear log folder -Use original Select Group -Correct init file -Active test units -Confirm 1 st result | Z13: 4 | AA13: Setup automated execution -Clear log folder -Use original Select Group -Correct init file -Active tes units -Confirm 1 st result

Sheet Cover
B3: G60 XXXX
B5: I-Step | C5: I-XXX
B6: Release_Software
B7: CRETA | C7: 0000XXXX-0XX.XXX.0XX
B10: 1.RELEASE TYPE
B11: 2.CUSTOMER SW RELEASE VERSION
B12: 3.APPLICATION LABEL | C12: SGBM - SWFL
C13: ID - 0000XXXX
C14: VER - 0XX.XXX.0XX
B15: 4.DATA LABEL | C15: SWFL AWD CHN DYN BBG BEV
C16: ID - 0000XXXX
C17: VER - 0XX.XXX.0XX
B18: 5.BOOT LOADER LABEL | C18: SGBM - BTLD
C19: ID - 0000A32E
C20: VER - 039.142.041
B22: Application version: | C22: 0000XXXX_ 0XX.XXX.0XX
B23: Data version: | C23: 0000XXXX_0XX.XXX.0XX

Sheet Definition
A2: Document Format
A3: Font: Calibri
A4: Font size: 11
A6: Status Definition
A7: OK | B7: means all test cases in html files pass and fully satisfy the the relevant requirements
A8: Partially cover | B8: means all test cases in html files pass but partially satisfy the the relevant requirements,, because some test case are not testable in ENG9 and tested in other ENG levels
A9: NG | B9: means all test cases in html files do not pass and deviations are not available
A10: Justify | B10: means all test cases in html files pass but not fully satisfy the the relevant requirements, and deviations or reasonable comment are written
A11: Obsolete | B11: means all test cases are not tested in ENG9 and refer to other ENG levels. Requirements are obsolete or not applicable
F18: `

Sheet L1_FI
A1: SP18 | J1: SP21 | V1: SP21P | W1: Reference | AG1: SPxx SOPyyyy Gxx aaaa.bb
A2: SOP2207 | B2: SOP2211 | C2: SOP2307 | D2: SOP2407 | E2: SOP2503 | F2: SOP2507 | G2: SOP2603 | H2: SOP2311 | I2: SOP2403 | J2: SOP2207 | K2: SOP2207_I20 | L2: SOP2211 | M2: SOP2303 | N2: SOP2307 | O2: SOP2407 | P2: SOP2311 | Q2: SOP2403 | R2: SOP2503 | S2: SOP2507 | T2: SOP2511 | U2: SOP2603 | V2: SOP2607 | W2: Test Case | X2: Pass | Y2: Fail | Z2: OtherFail | AA2: Total | AB2: Time | AC2: TSR ID | AD2: Status | AE2: Comments | AG2: Test Case | AH2: Pass | AI2: Fail | AJ2: OtherFail | AK2: Total | AL2: Time | AM2: Status | AN2: Comment | AO2: Test ID | AP2: Pass | AQ2: Fail | AR2: OtherFail | AS2: Total
A3: Yes | B3: Yes | C3: Yes | D3: Yes | E3: Yes | F3: Yes | G3: Yes | H3: Yes | I3: Yes | J3: Yes | K3: Yes | L3: Yes | M3: Yes | N3: Yes | O3: Yes | P3: Yes | Q3: Yes | R3: Yes | S3: Yes | T3: Yes | U3: Yes | V3: Yes | W3: [SYI_001_002_0003][FP101]Confirm DCDC over temperature detection.html | X3: 25 | Y3: 0 | Z3: 0 | AA3: 25 | AB3: 0.0022106481 | AO3: =EXACT(W3,AG3) | AP3: =EXACT(X3,AH3) | AQ3: =EXACT(Y3,AI3) | AR3: =EXACT(Z3,AJ3) | AS3: =EXACT(AA3,AK3)
A4: Yes | B4: Yes | C4: Yes | D4: Yes | E4: Yes | F4: Yes | G4: Yes | H4: Yes | I4: Yes | J4: No | K4: Yes | L4: No | M4: No | N4: No | O4: No | P4: No | Q4: No | R4: No | S4: No | T4: No | U4: No | V4: No | W4: [SYI_001_002_0004][FP102]Confirm DCDC Temp Range Check and Thermal Error Detect Check.html | X4: 24 | Y4: 0 | Z4: 0 | AA4: 24 | AB4: 0.0044907407 | AO4: =EXACT(W4,AG4) | AP4: =EXACT(X4,AH4) | AQ4: =EXACT(Y4,AI4) | AR4: =EXACT(Z4,AJ4) | AS4: =EXACT(AA4,AK4)
A5: No | B5: No | C5: No | D5: No | E5: No | F5: No | G5: No | H5: No | I5: No | J5: Yes | K5: No | L5: Yes | M5: Yes | N5: Yes | O5: Yes | P5: Yes | Q5: Yes | R5: Yes | S5: Yes | T5: Yes | U5: Yes | V5: Yes | W5: [SYI_001_002_0004][FP102]Confirm DCDC Temp Range Check and Thermal Error Detect Check_CR924.html | X5: 26 | Y5: 0 | Z5: 0 | AA5: 26 | AB5: 0.0044907407 | AE5: CR 924. Added additional 2 sub tc's according to task ticket #112322 | AO5: =EXACT(W5,AG5) | AP5: =EXACT(X5,AH5) | AQ5: =EXACT(Y5,AI5) | AR5: =EXACT(Z5,AJ5) | AS5: =EXACT(AA5,AK5)
A6: Yes | B6: Yes | C6: Yes | D6: Yes | E6: Yes | F6: Yes | G6: Yes | H6: Yes | I6: Yes | J6: No | K6: No | L6: No | M6: No | N6: No | O6: No | P6: No | Q6: No | R6: No | S6: No | T6: No | U6: No | V6: No | W6: [SYI_001_005_0004][FP102]Confirm DCDC Temp Range Check and Thermal Error Detect Check.html | X6: 16 | Y6: 0 | Z6: 0 | AA6: 16 | AB6: 0.0021527778 | AO6: =EXACT(W6,AG6) | AP6: =EXACT(X6,AH6) | AQ6: =EXACT(Y6,AI6) | AR6: =EXACT(Z6,AJ6) | AS6: =EXACT(AA6,AK6)
A7: No | B7: No | C7: No | D7: No | E7: No | F7: No | G7: No | H7: No | I7: No | J7: NA | K7: NA | L7: NA | M7: NA | N7: Yes | O7: Yes | P7: Yes | Q7: Yes | R7: Yes | S7: Yes | T7: Yes | U7: Yes | V7: Yes | W7: [SYI_001_005_0004][FP102]Confirm DCDC Temp Range Check and Thermal Error Detect Check_CR924.html | X7: 16 | Y7: 0 | Z7: 0 | AA7: 16 | AB7: 0.0021527778 | AO7: =EXACT(W7,AG7) | AP7: =EXACT(X7,AH7) | AQ7: =EXACT(Y7,AI7) | AR7: =EXACT(Z7,AJ7) | AS7: =EXACT(AA7,AK7)
A8: Yes | B8: Yes | C8: Yes | D8: Yes | E8: Yes | F8: Yes | G8: Yes | H8: Yes | I8: Yes | J8: Yes | K8: Yes | L8: Yes | M8: Yes | N8: Yes | O8: Yes | P8: Yes | Q8: Yes | R8: Yes | S8: Yes | T8: Yes | U8: Yes | V8: Yes | W8: [SYI_AC3_999_003]Requirements from other than KLH.html | X8: 1 | Y8: 0 | Z8: 0 | AA8: 1 | AB8: 0.0009375 | AC8: TSR-CCU-801 | AD8: Partially covered | AE8: SYI_AC3_999_003_001, SYI_AC3_999_003_002 are not tested and refer to ENG08 E/E (ENG8_NEO) (Traceability matrix sheet) Tested by SwReqspec_Comadapter 447 (SWR_96c7080b-f32c-563c-8819-45a0025d1226: E2E Protection in ComAdapter) | AO8: =EXACT(W8,AG8) | AP8: =EXACT(X8,AH8) | AQ8: =EXACT(Y8,AI8) | AR8: =EXACT(Z8,AJ8) | AS8: =EXACT(AA8,AK8)
A9: Yes | B9: Yes | C9: Yes | D9: Yes | E9: Yes | F9: Yes | G9: Yes | H9: Yes | I9: Yes | J9: Yes | K9: Yes | L9: Yes | M9: Yes | N9: Yes | O9: Yes | P9: Yes | Q9: Yes | R9: Yes | S9: Yes | T9: Yes | U9: Yes | V9: Yes | W9: [SYI_AC3_999_004]Requirements from other than KLH.html | X9: 2 | Y9: 0 | Z9: 0 | AA9: 2 | AB9: 0.0003125 | AC9: TSR-CCU-803 | AO9: =EXACT(W9,AG9) | AP9: =EXACT(X9,AH9) | AQ9: =EXACT(Y9,AI9) | AR9: =EXACT(Z9,AJ9) | AS9: =EXACT(AA9,AK9)
A10: Yes | B10: Yes | C10: Yes | D10: Yes | E10: Yes | F10: Yes | G10: Yes | H10: Yes | I10: Yes | J10: Yes | K10: Yes | L10: Yes | M10: Yes | N10: Yes | O10: Yes | P10: Yes | Q10: Yes | R10: Yes | S10: Yes | T10: Yes | U10: Yes | V10: Yes | W10: [SYI_AC3_999_005]Requirements from other than KLH.html | X10: 2 | Y10: 0 | Z10: 0 | AA10: 2 | AB10: 0.0003125 | AC10: TSR-CCU-803 | AO10: =EXACT(W10,AG10) | AP10: =EXACT(X10,AH10) | AQ10: =EXACT(Y10,AI10) | AR10: =EXACT(Z10,AJ10) | AS10: =EXACT(AA10,AK10)
A11: Yes | B11: Yes | C11: Yes | D11: Yes | E11: Yes | F11: Yes | G11: Yes | H11: Yes | I11: Yes | J11: Yes | K11: Yes | L11: Yes | M11: Yes | N11: Yes | O11: Yes | P11: Yes | Q11: Yes | R11: Yes | S11: Yes | T11: Yes | U11: Yes | V11: Yes | W11: [SYI_AC3_999_006]Requirements from other than KLH.html | X11: 2 | Y11: 0 | Z11: 0 | AA11: 2 | AB11: 0.0003125 | AC11: TSR-CCU-805 | AO11: =EXACT(W11,AG11) | AP11: =EXACT(X11,AH11) | AQ11: =EXACT(Y11,AI11) | AR11: =EXACT(Z11,AJ11) | AS11: =EXACT(AA11,AK11)
A12: Yes | B12: Yes | C12: Yes | D12: Yes | E12: Yes | F12: Yes | G12: Yes | H12: Yes | I12: Yes | J12: Yes | K12: Yes | L12: Yes | M12: Yes | N12: Yes | O12: Yes | P12: Yes | Q12: Yes | R12: Yes | S12: Yes | T12: Yes | U12: Yes | V12: Yes | W12: [SYI_AC3_999_007]Requirements from other than KLH.html | X12: 2 | Y12: 0 | Z12: 0 | AA12: 2 | AB12: 0.0003125 | AC12: TSR-CCU-805 | AO12: =EXACT(W12,AG12) | AP12: =EXACT(X12,AH12) | AQ12: =EXACT(Y12,AI12) | AR12: =EXACT(Z12,AJ12) | AS12: =EXACT(AA12,AK12)
A13: Yes | B13: Yes | C13: Yes | D13: Yes | E13: Yes | F13: Yes | G13: Yes | H13: Yes | I13: Yes | J13: Yes | K13: Yes | L13: Yes | M13: Yes | N13: Yes | O13: Yes | P13: Yes | Q13: Yes | R13: Yes | S13: Yes | T13: Yes | U13: Yes | V13: Yes | W13: [SYI_AC3_999_008]Requirements from other than KLH.html | X13: 1 | Y13: 0 | Z13: 0 | AA13: 1 | AB13: 0.00059027778 | AC13: TSR-CCU-802 | AD13: Partially covered | AE13: SYI_AC3_999_008_001, SYI_AC3_999_008_002 are not tested and refer to Eng 8 (Traceability matrix sheet) SWQT_031_001_0012, SWQT_031_001_0017 | AO13: =EXACT(W13,AG13) | AP13: =EXACT(X13,AH13) | AQ13: =EXACT(Y13,AI13) | AR13: =EXACT(Z13,AJ13) | AS13: =EXACT(AA13,AK13)
A14: Yes | B14: Yes | C14: Yes | D14: Yes | E14: Yes | F14: Yes | G14: Yes | H14: Yes | I14: Yes | J14: Yes | K14: Yes | L14: Yes | M14: Yes | N14: Yes | O14: Yes | P14: Yes | Q14: Yes | R14: Yes | S14: Yes | T14: Yes | U14: Yes | V14: Yes | W14: [SYI_COMMON_003_001_001_001] Chorus SPI received No error L1.html | X14: 1 | Y14: 0 | Z14: 0 | AA14: 1 | AB14: 0.00053240741 | AC14: No TSR ID | AO14: =EXACT(W14,AG14) | AP14: =EXACT(X14,AH14) | AQ14: =EXACT(Y14,AI14) | AR14: =EXACT(Z14,AJ14) | AS14: =EXACT(AA14,AK14)
A15: Yes | B15: Yes | C15: Yes | D15: Yes | E15: Yes | F15: Yes | G15: Yes | H15: Yes | I15: Yes | J15: Yes | K15: Yes | L15: Yes | M15: Yes | N15: Yes | O15: Yes | P15: Yes | Q15: Yes | R15: Yes | S15: Yes | T15: Yes | U15: Yes | V15: Yes | W15: [SYI_COMMON_003_001_001_002] Chorus SPI received No error L2.html | X15: 1 | Y15: 0 | Z15: 0 | AA15: 1 | AB15: 0.00033564815 | AC15: No TSR ID | AO15: =EXACT(W15,AG15) | AP15: =EXACT(X15,AH15) | AQ15: =EXACT(Y15,AI15) | AR15: =EXACT(Z15,AJ15) | AS15: =EXACT(AA15,AK15)
A16: Yes | B16: Yes | C16: Yes | D16: Yes | E16: Yes | F16: Yes | G16: Yes | H16: Yes | I16: Yes | J16: Yes | K16: Yes | L16: Yes | M16: Yes | N16: Yes | O16: Yes | P16: Yes | Q16: Yes | R16: Yes | S16: Yes | T16: Yes | U16: Yes | V16: Yes | W16: [SYI_COMMON_003_001_001_003] Chorus SPI received No error L3.html | X16: 1 | Y16: 0 | Z16: 0 | AA16: 1 | AB16: 0.00033564815 | AC16: No TSR ID | AO16: =EXACT(W16,AG16) | AP16: =EXACT(X16,AH16) | AQ16: =EXACT(Y16,AI16) | AR16: =EXACT(Z16,AJ16) | AS16: =EXACT(AA16,AK16)
A17: Yes | B17: Yes | C17: Yes | D17: Yes | E17: Yes | F17: Yes | G17: Yes | H17: Yes | I17: Yes | J17: Yes | K17: Yes | L17: Yes | M17: Yes | N17: Yes | O17: Yes | P17: Yes | Q17: Yes | R17: Yes | S17: Yes | T17: Yes | U17: Yes | V17: Yes | W17: [SYI_COMMON_003_001_003_001] Chorus SPI received SOF error L1.html | X17: 1 | Y17: 0 | Z17: 0 | AA17: 1 | AB17: 0.00034722222 | AC17: No TSR ID | AO17: =EXACT(W17,AG17) | AP17: =EXACT(X17,AH17) | AQ17: =EXACT(Y17,AI17) | AR17: =EXACT(Z17,AJ17) | AS17: =EXACT(AA17,AK17)
A18: Yes | B18: Yes | C18: Yes | D18: Yes | E18: Yes | F18: Yes | G18: Yes | H18: Yes | I18: Yes | J18: Yes | K18: Yes | L18: Yes | M18: Yes | N18: Yes | O18: Yes | P18: Yes | Q18: Yes | R18: Yes | S18: Yes | T18: Yes | U18: Yes | V18: Yes | W18: [SYI_COMMON_003_001_003_002] Chorus SPI received SOF error L2.html | X18: 1 | Y18: 0 | Z18: 0 | AA18: 1 | AB18: 0.00033564815 | AC18: No TSR ID | AO18: =EXACT(W18,AG18) | AP18: =EXACT(X18,AH18) | AQ18: =EXACT(Y18,AI18) | AR18: =EXACT(Z18,AJ18) | AS18: =EXACT(AA18,AK18)
A19: Yes | B19: Yes | C19: Yes | D19: Yes | E19: Yes | F19: Yes | G19: Yes | H19: Yes | I19: Yes | J19: Yes | K19: Yes | L19: Yes | M19: Yes | N19: Yes | O19: Yes | P19: Yes | Q19: Yes | R19: Yes | S19: Yes | T19: Yes | U19: Yes | V19: Yes | W19: [SYI_COMMON_003_001_003_003] Chorus SPI received SOF error L3.html | X19: 1 | Y19: 0 | Z19: 0 | AA19: 1 | AB19: 0.00033564815 | AC19: No TSR ID | AO19: =EXACT(W19,AG19) | AP19: =EXACT(X19,AH19) | AQ19: =EXACT(Y19,AI19) | AR19: =EXACT(Z19,AJ19) | AS19: =EXACT(AA19,AK19)
A20: Yes | B20: Yes | C20: Yes | D20: Yes | E20: Yes | F20: Yes | G20: Yes | H20: Yes | I20: Yes | J20: Yes | K20: Yes | L20: Yes | M20: Yes | N20: Yes | O20: Yes | P20: Yes | Q20: Yes | R20: Yes | S20: Yes | T20: Yes | U20: Yes | V20: Yes | W20: [SYI_COMMON_003_001_004_001] Chorus SPI received SubFrame error L1.html | X20: 1 | Y20: 0 | Z20: 0 | AA20: 1 | AB20: 0.00033564815 | AC20: No TSR ID | AO20: =EXACT(W20,AG20) | AP20: =EXACT(X20,AH20) | AQ20: =EXACT(Y20,AI20) | AR20: =EXACT(Z20,AJ20) | AS20: =EXACT(AA20,AK20)
A21: Yes | B21: Yes | C21: Yes | D21: Yes | E21: Yes | F21: Yes | G21: Yes | H21: Yes | I21: Yes | J21: Yes | K21: Yes | L21: Yes | M21: Yes | N21: Yes | O21: Yes | P21: Yes | Q21: Yes | R21: Yes | S21: Yes | T21: Yes | U21: Yes | V21: Yes | W21: [SYI_COMMON_003_001_004_002] Chorus SPI received SubFrame error L2.html | X21: 1 | Y21: 0 | Z21: 0 | AA21: 1 | AB21: 0.00033564815 | AC21: No TSR ID | AO21: =EXACT(W21,AG21) | AP21: =EXACT(X21,AH21) | AQ21: =EXACT(Y21,AI21) | AR21: =EXACT(Z21,AJ21) | AS21: =EXACT(AA21,AK21)
A22: Yes | B22: Yes | C22: Yes | D22: Yes | E22: Yes | F22: Yes | G22: Yes | H22: Yes | I22: Yes | J22: Yes | K22: Yes | L22: Yes | M22: Yes | N22: Yes | O22: Yes | P22: Yes | Q22: Yes | R22: Yes | S22: Yes | T22: Yes | U22: Yes | V22: Yes | W22: [SYI_COMMON_003_001_004_003] Chorus SPI received SubFrame error L3.html | X22: 1 | Y22: 0 | Z22: 0 | AA22: 1 | AB22: 0.00033564815 | AC22: No TSR ID | AO22: =EXACT(W22,AG22) | AP22: =EXACT(X22,AH22) | AQ22: =EXACT(Y22,AI22) | AR22: =EXACT(Z22,AJ22) | AS22: =EXACT(AA22,AK22)
A23: Yes | B23: Yes | C23: Yes | D23: Yes | E23: Yes | F23: Yes | G23: Yes | H23: Yes | I23: Yes | J23: Yes | K23: Yes | L23: Yes | M23: Yes | N23: Yes | O23: Yes | P23: Yes | Q23: Yes | R23: Yes | S23: Yes | T23: Yes | U23: Yes | V23: Yes | W23: [SYI_COMMON_003_001_005_001] Chorus SPI received Alive counter error L1.html | X23: 1 | Y23: 0 | Z23: 0 | AA23: 1 | AB23: 0.00033564815 | AC23: No TSR ID | AO23: =EXACT(W23,AG23) | AP23: =EXACT(X23,AH23) | AQ23: =EXACT(Y23,AI23) | AR23: =EXACT(Z23,AJ23) | AS23: =EXACT(AA23,AK23)
A24: Yes | B24: Yes | C24: Yes | D24: Yes | E24: Yes | F24: Yes | G24: Yes | H24: Yes | I24: Yes | J24: Yes | K24: Yes | L24: Yes | M24: Yes | N24: Yes | O24: Yes | P24: Yes | Q24: Yes | R24: Yes | S24: Yes | T24: Yes | U24: Yes | V24: Yes | W24: [SYI_COMMON_003_001_005_002] Chorus SPI received Alive counter error L2.html | X24: 1 | Y24: 0 | Z24: 0 | AA24: 1 | AB24: 0.00033564815 | AC24: No TSR ID | AO24: =EXACT(W24,AG24) | AP24: =EXACT(X24,AH24) | AQ24: =EXACT(Y24,AI24) | AR24: =EXACT(Z24,AJ24) | AS24: =EXACT(AA24,AK24)
A25: Yes | B25: Yes | C25: Yes | D25: Yes | E25: Yes | F25: Yes | G25: Yes | H25: Yes | I25: Yes | J25: Yes | K25: Yes | L25: Yes | M25: Yes | N25: Yes | O25: Yes | P25: Yes | Q25: Yes | R25: Yes | S25: Yes | T25: Yes | U25: Yes | V25: Yes | W25: [SYI_COMMON_003_001_005_003] Chorus SPI received Alive counter error L3.html | X25: 1 | Y25: 0 | Z25: 0 | AA25: 1 | AB25: 0.00033564815 | AC25: No TSR ID | AO25: =EXACT(W25,AG25) | AP25: =EXACT(X25,AH25) | AQ25: =EXACT(Y25,AI25) | AR25: =EXACT(Z25,AJ25) | AS25: =EXACT(AA25,AK25)
... A45: Yes | B45: Yes | C45: Yes | D45: Yes | E45: Yes | F45: Yes | G45: Yes | H45: Yes | I45: Yes | J45: Yes | K45: Yes | L45: Yes | M45: Yes | N45: Yes | O45: Yes | P45: Yes | Q45: Yes | R45: Yes | S45: Yes | T45: Yes | U45: Yes | V45: Yes | W45: [SYI_COMMON_004_001_002] I2C Bus Lock I2C error.html | X45: 1 | Y45: 0 | Z45: 0 | AA45: 1 | AB45: 0.00046296296 | AC45: No TSR ID | AO45: =EXACT(W45,AG45) | AP45: =EXACT(X45,AH45) | AQ45: =EXACT(Y45,AI45) | AR45: =EXACT(Z45,AJ45) | AS45: =EXACT(AA45,AK45)
A46: Yes | B46: Yes | C46: Yes | D46: Yes | E46: Yes | F46: Yes | G46: Yes | H46: Yes | I46: Yes | J46: Yes | K46: Yes | L46: Yes | M46: Yes | N46: Yes | O46: Yes | P46: Yes | Q46: Yes | R46: Yes | S46: Yes | T46: Yes | U46: Yes | V46: Yes | W46: [SYI_FP20_001_002] PFC over temperature detection.html | X46: 6 | Y46: 0 | Z46: 0 | AA46: 6 | AC46: TSR-CCU-351 | AO46: =EXACT(W46,AG46) | AP46: =EXACT(X46,AH46) | AQ46: =EXACT(Y46,AI46) | AR46: =EXACT(Z46,AJ46) | AS46: =EXACT(AA46,AK46)
A47: Yes | B47: Yes | C47: Yes | D47: Yes | E47: Yes | F47: Yes | G47: Yes | H47: Yes | I47: Yes | J47: Yes | K47: Yes | L47: Yes | M47: Yes | N47: Yes | O47: Yes | P47: Yes | Q47: Yes | R47: Yes | S47: Yes | T47: Yes | U47: Yes | V47: Yes | W47: [SYI_FP20_002_002] PFC Temp Range Check and Thermal Error Detect Check.html | X47: 6 | Y47: 0 | Z47: 0 | AA47: 6 | AC47: TSR-CCU-360 | AO47: =EXACT(W47,AG47) | AP47: =EXACT(X47,AH47) | AQ47: =EXACT(Y47,AI47) | AR47: =EXACT(Z47,AJ47) | AS47: =EXACT(AA47,AK47)
A48: Yes | B48: Yes | C48: Yes | D48: Yes | E48: Yes | F48: Yes | G48: Yes | H48: Yes | I48: Yes | J48: Yes | K48: Yes | L48: Yes | M48: Yes | N48: Yes | O48: Yes | P48: Yes | Q48: Yes | R48: Yes | S48: Yes | T48: Yes | U48: Yes | V48: Yes | W48: [SYI_FP20_002_003] PFC Temp Range Check and Thermal Error Detect Check.html | X48: 3 | Y48: 3 | Z48: 0 | AA48: 6 | AC48: TSR-CCU-361 | AD48: Justify | AE48: In ENG09 Test Environment cannot simulate PFC/CHG Temperature below -5 C properly due to limitation of Test Environment, this point has been raised and discussed in the ticket KAP#122475. The issue is JUSTIFIED by MF as a test bench limitation and ENG.05 HW test case IDs will be referenced for Verification coverage. | AO48: =EXACT(W48,AG48) | AP48: =EXACT(X48,AH48) | AQ48: =EXACT(Y48,AI48) | AR48: =EXACT(Z48,AJ48) | AS48: =EXACT(AA48,AK48)
A49: Yes | B49: Yes | C49: Yes | D49: Yes | E49: Yes | F49: Yes | G49: Yes | H49: Yes | I49: Yes | J49: Yes | K49: Yes | L49: Yes | M49: Yes | N49: Yes | O49: Yes | P49: Yes | Q49: Yes | R49: Yes | S49: Yes | T49: Yes | U49: Yes | V49: Yes | W49: [SYI_FP20_002_006] PFC Temp Range Check and Thermal Error Detect Check.html | X49: 12 | Y49: 0 | Z49: 0 | AA49: 12 | AC49: TSR-CCU-389 | AO49: =EXACT(W49,AG49) | AP49: =EXACT(X49,AH49) | AQ49: =EXACT(Y49,AI49) | AR49: =EXACT(Z49,AJ49) | AS49: =EXACT(AA49,AK49)
A50: Yes | B50: Yes | C50: Yes | D50: Yes | E50: Yes | F50: Yes | G50: Yes | H50: Yes | I50: Yes | J50: Yes | K50: Yes | L50: Yes | M50: Yes | N50: Yes | O50: Yes | P50: Yes | Q50: Yes | R50: Yes | S50: Yes | T50: Yes | U50: Yes | V50: Yes | W50: [SYI_FP30_001_002] CHG over temperature detection.html | X50: 6 | Y50: 0 | Z50: 0 | AA50: 6 | AC50: TSR-CCU-352 | AO50: =EXACT(W50,AG50) | AP50: =EXACT(X50,AH50) | AQ50: =EXACT(Y50,AI50) | AR50: =EXACT(Z50,AJ50) | AS50: =EXACT(AA50,AK50)
A51: Yes | B51: Yes | C51: Yes | D51: Yes | E51: Yes | F51: Yes | G51: Yes | H51: Yes | I51: Yes | J51: Yes | K51: Yes | L51: Yes | M51: Yes | N51: Yes | O51: Yes | P51: Yes | Q51: Yes | R51: Yes | S51: Yes | T51: Yes | U51: Yes | V51: Yes | W51: [SYI_FP30_002_002] CHG Temp Range Check and Thermal Error Detect Check.html | X51: 6 | Y51: 0 | Z51: 0 | AA51: 6 | AC51: TSR-CCU-364 | AO51: =EXACT(W51,AG51) | AP51: =EXACT(X51,AH51) | AQ51: =EXACT(Y51,AI51) | AR51: =EXACT(Z51,AJ51) | AS51: =EXACT(AA51,AK51)
A52: Yes | B52: Yes | C52: Yes | D52: Yes | E52: Yes | F52: Yes | G52: Yes | H52: Yes | I52: Yes | J52: Yes | K52: Yes | L52: Yes | M52: Yes | N52: Yes | O52: Yes | P52: Yes | Q52: Yes | R52: Yes | S52: Yes | T52: Yes | U52: Yes | V52: Yes | W52: [SYI_FP30_002_003] CHG Temp Range Check and Thermal Error Detect Check.html | X52: 3 | Y52: 3 | Z52: 0 | AA52: 6 | AC52: TSR-CCU-365 | AD52: Justify | AE52: In ENG09 Test Environment cannot simulate PFC/CHG Temperature below -5 C properly due to limitation of Test Environment, this point has been raised and discussed in the ticket KAP#122475. The issue is JUSTIFIED by MF as a test bench limitation and ENG.05 HW test case IDs will be referenced for Verification coverage. | AO52: =EXACT(W52,AG52) | AP52: =EXACT(X52,AH52) | AQ52: =EXACT(Y52,AI52) | AR52: =EXACT(Z52,AJ52) | AS52: =EXACT(AA52,AK52)
A53: Yes | B53: Yes | C53: Yes | D53: Yes | E53: Yes | F53: Yes | G53: Yes | H53: Yes | I53: Yes | J53: Yes | K53: Yes | L53: Yes | M53: Yes | N53: Yes | O53: Yes | P53: Yes | Q53: Yes | R53: Yes | S53: Yes | T53: Yes | U53: Yes | V53: Yes | W53: [SYI_FP30_002_006] CHG Temp Range Check and Thermal Error Detect Check.html | X53: 12 | Y53: 0 | Z53: 0 | AA53: 12 | AC53: TSR-CCU-389 | AO53: =EXACT(W53,AG53) | AP53: =EXACT(X53,AH53) | AQ53: =EXACT(Y53,AI53) | AR53: =EXACT(Z53,AJ53) | AS53: =EXACT(AA53,AK53)
A54: Yes | B54: Yes | C54: Yes | D54: Yes | E54: Yes | F54: Yes | G54: Yes | H54: Yes | I54: Yes | J54: Yes | K54: Yes | L54: Yes | M54: Yes | N54: Yes | O54: Yes | P54: Yes | Q54: Yes | R54: Yes | S54: Yes | T54: Yes | U54: Yes | V54: Yes | W54: [SYI_SF02_001_008]Accelerator pedal plausibility.html | X54: 2 | Y54: 0 | Z54: 0 | AA54: 2 | AC54: TSR-CCU-471 | AO54: =EXACT(W54,AG54) | AP54: =EXACT(X54,AH54) | AQ54: =EXACT(Y54,AI54) | AR54: =EXACT(Z54,AJ54) | AS54: =EXACT(AA54,AK54)
A55: Yes | B55: Yes | C55: Yes | D55: Yes | E55: Yes | F55: Yes | G55: Yes | H55: Yes | I55: Yes | J55: Yes | K55: Yes | L55: Yes | M55: Yes | N55: Yes | O55: Yes | P55: Yes | Q55: Yes | R55: Yes | S55: Yes | T55: Yes | U55: Yes | V55: Yes | W55: [SYI_SF02_001_010]Accelerator pedal plausibility.html | X55: 2 | Y55: 0 | Z55: 0 | AA55: 2 | AC55: TSR-CCU-473 | AO55: =EXACT(W55,AG55) | AP55: =EXACT(X55,AH55) | AQ55: =EXACT(Y55,AI55) | AR55: =EXACT(Z55,AJ55) | AS55: =EXACT(AA55,AK55)
A56: Yes | B56: Yes | C56: Yes | D56: Yes | E56: Yes | F56: Yes | G56: Yes | H56: Yes | I56: Yes | J56: Yes | K56: Yes | L56: Yes | M56: Yes | N56: Yes | O56: Yes | P56: Yes | Q56: Yes | R56: Yes | S56: Yes | T56: Yes | U56: Yes | V56: Yes | W56: [SYI_SF02_006_002]Pedal sensor fault check.html | X56: 3 | Y56: 0 | Z56: 0 | AA56: 3 | AC56: TSR-CCU-728 | AO56: =EXACT(W56,AG56) | AP56: =EXACT(X56,AH56) | AQ56: =EXACT(Y56,AI56) | AR56: =EXACT(Z56,AJ56) | AS56: =EXACT(AA56,AK56)
A57: Yes | B57: Yes | C57: Yes | D57: Yes | E57: Yes | F57: Yes | G57: Yes | H57: Yes | I57: Yes | J57: Yes | K57: Yes | L57: Yes | M57: Yes | N57: Yes | O57: Yes | P57: Yes | Q57: Yes | R57: Yes | S57: Yes | T57: Yes | U57: Yes | V57: Yes | W57: [SYI_SF02_006_003]Pedal sensor fault check.html | X57: 3 | Y57: 0 | Z57: 0 | AA57: 3 | AC57: TSR-CCU-729 | AO57: =EXACT(W57,AG57) | AP57: =EXACT(X57,AH57) | AQ57: =EXACT(Y57,AI57) | AR57: =EXACT(Z57,AJ57) | AS57: =EXACT(AA57,AK57)
W58: Total | X58: =SUM(X3:X57) | Y58: =SUM(Y3:Y57) | Z58: =SUM(Z3:Z57) | AA58: =SUM(AA3:AA57) | AG58: Total | AH58: =SUM(AH3:AH57) | AI58: =SUM(AI3:AI57) | AJ58: =SUM(AJ3:AJ57) | AK58: =SUM(AK3:AK57) | AO58: =EXACT(W58,AG58) | AP58: =EXACT(X58,AH58) | AQ58: =EXACT(Y58,AI58) | AR58: =EXACT(Z58,AJ58) | AS58: =EXACT(AA58,AK58)
A64: Additional HTML Files

Sheet FuSa_Charger
A1: SP18 | J1: SP21 | V1: SP21P | W1: Reference | AG1: SPxx SOPyyyy Gxx aaaa.bb
A2: SOP2207 | B2: SOP2211 | C2: SOP2307 | D2: SOP2407 | E2: SOP2503 | F2: SOP2507 | G2: SOP2603 | H2: SOP2311 | I2: SOP2403 | J2: SOP2207 | K2: SOP2207_I20 | L2: SOP2211 | M2: SOP2303 | N2: SOP2307 | O2: SOP2407 | P2: SOP2311 | Q2: SOP2403 | R2: SOP2503 | S2: SOP2507 | T2: SOP2511 | U2: SOP2603 | V2: SOP2607 | W2: Test Case | X2: Pass | Y2: Fail | Z2: OtherFail | AA2: Total | AB2: Time | AC2: TSR-ID | AD2: Status | AE2: Comment | AG2: Test Case | AH2: Pass | AI2: Fail | AJ2: OtherFail | AK2: Total | AL2: Time | AM2: Status | AN2: Comment | AO2: TC | AP2: Pass | AQ2: Fail | AR2: Other fail | AS2: Total
A3: Yes | B3: Yes | C3: Yes | D3: Yes | E3: Yes | F3: Yes | G3: Yes | H3: Yes | I3: Yes | J3: Yes | K3: Yes | L3: Yes | M3: Yes | N3: Yes | O3: Yes | P3: Yes | Q3: Yes | R3: Yes | S3: Yes | T3: Yes | U3: Yes | V3: Yes | W3: [COMMON][SYI_COMMON_002_001].html | X3: 19 | Y3: 7 | Z3: 0 | AA3: 26 | AC3: TSR-CCU-342 | AD3: Justify | AE3: Expect to be failed on TB5, due to EA Power Supply limitation In ENG09 Test Environment cannot simulate PFC/CHG Temperature below -5 C properly due to limitation of Test Environment, this point has been raised and discussed in the ticket KAP#122475. The issue is JUSTIFIED by MF as a test bench limitation and ENG.05 HW test case IDs will be referenced for Verification coverage. | AG3: [COMMON][SYI_COMMON_002_001].html | AH3: 19 | AI3: 7 | AJ3: 0 | AK3: 26 | AO3: =EXACT(W3,AG3) | AP3: =EXACT(X3,AH3) | AQ3: =EXACT(Y3,AI3) | AR3: =EXACT(Z3,AJ3) | AS3: =EXACT(AA3,AK3) | AT3: 0000BA6C_009_030_063 | AU3: 0000BA78_009_030_061
A4: No | B4: No | C4: No | D4: No | E4: No | F4: No | G4: No | H4: No | I4: No | J4: No | K4: No | L4: No | M4: No | N4: No | O4: No | P4: No | Q4: No | R4: No | S4: No | T4: No | U4: No | V4: No | W4: [SYI_AC3_001_001]Limiting the charging voltage on the HV DC circuit.html | X4: 3 | Y4: 0 | Z4: 0 | AA4: 3 | AC4: TSR-CCU-053 | AD4: Obsolete | AE4: Refer to ENG10 (Traceability matrix sheet ) | AO4: =EXACT(W4,AG4) | AP4: =EXACT(X4,AH4) | AQ4: =EXACT(Y4,AI4) | AR4: =EXACT(Z4,AJ4) | AS4: =EXACT(AA4,AK4)
A5: Yes | B5: Yes | C5: Yes | D5: Yes | E5: Yes | F5: Yes | G5: Yes | H5: Yes | I5: Yes | J5: Yes | K5: Yes | L5: Yes | M5: Yes | N5: Yes | O5: Yes | P5: Yes | Q5: Yes | R5: Yes | S5: Yes | T5: Yes | U5: Yes | V5: Yes | W5: [SYI_AC3_001_002]Limiting the charging voltage on the HV DC circuit.html | X5: 2 | Y5: 0 | Z5: 0 | AA5: 2 | AC5: TSR-CCU-055 | AG5: [SYI_AC3_001_002]Limiting the charging voltage on the HV DC circuit.html | AH5: 2 | AI5: 0 | AJ5: 0 | AK5: 2 | AO5: =EXACT(W5,AG5) | AP5: =EXACT(X5,AH5) | AQ5: =EXACT(Y5,AI5) | AR5: =EXACT(Z5,AJ5) | AS5: =EXACT(AA5,AK5) | AT5: 0000BA6C_009_030_063 | AU5: 0000BA78_009_030_061
A6: Yes | B6: Yes | C6: Yes | D6: Yes | E6: Yes | F6: Yes | G6: Yes | H6: Yes | I6: Yes | J6: Yes | K6: Yes | L6: Yes | M6: Yes | N6: Yes | O6: Yes | P6: Yes | Q6: Yes | R6: Yes | S6: Yes | T6: Yes | U6: Yes | V6: Yes | W6: [SYI_AC3_001_003]Limiting the charging voltage on the HV DC circuit.html | X6: 2 | Y6: 0 | Z6: 0 | AA6: 2 | AC6: TSR-CCU-014 | AG6: [SYI_AC3_001_003]Limiting the charging voltage on the HV DC circuit.html | AH6: 2 | AI6: 0 | AJ6: 0 | AK6: 2 | AO6: =EXACT(W6,AG6) | AP6: =EXACT(X6,AH6) | AQ6: =EXACT(Y6,AI6) | AR6: =EXACT(Z6,AJ6) | AS6: =EXACT(AA6,AK6) | AT6: 0000BA6C_009_030_063 | AU6: 0000BA78_009_030_061
A7: Yes | B7: Yes | C7: Yes | D7: Yes | E7: Yes | F7: Yes | G7: Yes | H7: Yes | I7: Yes | J7: Yes | K7: Yes | L7: Yes | M7: Yes | N7: Yes | O7: Yes | P7: Yes | Q7: Yes | R7: Yes | S7: Yes | T7: Yes | U7: Yes | V7: Yes | W7: [SYI_AC3_001_005]Limiting the charging voltage on the HV DC circuit.html | X7: 2 | Y7: 0 | Z7: 0 | AA7: 2 | AC7: TSR-CCU-028 | AG7: [SYI_AC3_001_005]Limiting the charging voltage on the HV DC circuit.html | AH7: 2 | AI7: 0 | AJ7: 0 | AK7: 2 | AO7: =EXACT(W7,AG7) | AP7: =EXACT(X7,AH7) | AQ7: =EXACT(Y7,AI7) | AR7: =EXACT(Z7,AJ7) | AS7: =EXACT(AA7,AK7) | AT7: 0000BA6C_009_030_063 | AU7: 0000BA78_009_030_061
A8: Yes | B8: Yes | C8: Yes | D8: Yes | E8: Yes | F8: Yes | G8: Yes | H8: Yes | I8: Yes | J8: Yes | K8: Yes | L8: Yes | M8: Yes | N8: Yes | O8: Yes | P8: Yes | Q8: Yes | R8: Yes | S8: Yes | T8: Yes | U8: Yes | V8: Yes | W8: [SYI_AC3_001_006]Limiting the charging voltage on the HV DC circuit.html | X8: 2 | Y8: 0 | Z8: 0 | AA8: 2 | AC8: TSR-CCU-029 | AG8: [SYI_AC3_001_006]Limiting the charging voltage on the HV DC circuit.html | AH8: 2 | AI8: 0 | AJ8: 0 | AK8: 2 | AO8: =EXACT(W8,AG8) | AP8: =EXACT(X8,AH8) | AQ8: =EXACT(Y8,AI8) | AR8: =EXACT(Z8,AJ8) | AS8: =EXACT(AA8,AK8) | AT8: 0000BA6C_009_030_063 | AU8: 0000BA78_009_030_061
A9: Yes | B9: Yes | C9: Yes | D9: Yes | E9: Yes | F9: Yes | G9: Yes | H9: Yes | I9: Yes | J9: Yes | K9: Yes | L9: Yes | M9: Yes | N9: Yes | O9: Yes | P9: Yes | Q9: Yes | R9: Yes | S9: Yes | T9: Yes | U9: Yes | V9: Yes | W9: [SYI_AC3_001_008]Limiting the charging voltage on the HV DC circuit.html | X9: 2 | Y9: 0 | Z9: 0 | AA9: 2 | AC9: TSR-CCU-001 | AG9: [SYI_AC3_001_008]Limiting the charging voltage on the HV DC circuit.html | AH9: 2 | AI9: 0 | AJ9: 0 | AK9: 2 | AO9: =EXACT(W9,AG9) | AP9: =EXACT(X9,AH9) | AQ9: =EXACT(Y9,AI9) | AR9: =EXACT(Z9,AJ9) | AS9: =EXACT(AA9,AK9) | AT9: 0000BA6C_009_030_063 | AU9: 0000BA78_009_030_061
A10: Yes | B10: Yes | C10: Yes | D10: Yes | E10: Yes | F10: Yes | G10: Yes | H10: Yes | I10: Yes | J10: Yes | K10: Yes | L10: Yes | M10: Yes | N10: Yes | O10: Yes | P10: Yes | Q10: Yes | R10: Yes | S10: Yes | T10: Yes | U10: Yes | V10: Yes | W10: [SYI_AC3_001_009]Limiting the charging voltage on the HV DC circuit.html | X10: 2 | Y10: 0 | Z10: 0 | AA10: 2 | AC10: TSR-CCU-003 | AG10: [SYI_AC3_001_009]Limiting the charging voltage on the HV DC circuit.html | AH10: 1 | AI10: 1 | AJ10: 4 | AK10: 2 | AO10: =EXACT(W10,AG10) | AP10: =EXACT(X10,AH10) | AQ10: =EXACT(Y10,AI10) | AR10: =EXACT(Z10,AJ10) | AS10: =EXACT(AA10,AK10) | AT10: 0000BA6C_009_030_063 | AU10: 0000BA78_009_030_061
A11: No | B11: No | C11: No | D11: No | E11: No | F11: No | G11: No | H11: No | I11: No | J11: No | K11: No | L11: No | M11: No | N11: No | O11: No | P11: No | Q11: No | R11: No | S11: No | T11: No | U11: No | V11: No | W11: [SYI_AC3_001_010]Limiting the charging voltage on the HV DC circuit.html | X11: 4 | Y11: 0 | Z11: 0 | AA11: 4 | AC11: TSR-CCU-054 | AD11: Obsolete | AE11: Refer to ENG10 (Traceability matrix sheet ) | AO11: =EXACT(W11,AG11) | AP11: =EXACT(X11,AH11) | AQ11: =EXACT(Y11,AI11) | AR11: =EXACT(Z11,AJ11) | AS11: =EXACT(AA11,AK11)
A12: Yes | B12: Yes | C12: Yes | D12: Yes | E12: Yes | F12: Yes | G12: Yes | H12: Yes | I12: Yes | J12: Yes | K12: Yes | L12: Yes | M12: Yes | N12: Yes | O12: Yes | P12: Yes | Q12: Yes | R12: Yes | S12: Yes | T12: Yes | U12: Yes | V12: Yes | W12: [SYI_AC3_001_011]Limiting the charging voltage on the HV DC circuit.html | X12: 2 | Y12: 0 | Z12: 0 | AA12: 2 | AC12: TSR-CCU-056 | AG12: [SYI_AC3_001_011]Limiting the charging voltage on the HV DC circuit.html | AH12: 2 | AI12: 0 | AJ12: 0 | AK12: 2 | AO12: =EXACT(W12,AG12) | AP12: =EXACT(X12,AH12) | AQ12: =EXACT(Y12,AI12) | AR12: =EXACT(Z12,AJ12) | AS12: =EXACT(AA12,AK12) | AT12: 0000BA6C_009_030_063 | AU12: 0000BA78_009_030_061
A13: Yes | B13: Yes | C13: Yes | D13: Yes | E13: Yes | F13: Yes | G13: Yes | H13: Yes | I13: Yes | J13: Yes | K13: Yes | L13: Yes | M13: Yes | N13: Yes | O13: Yes | P13: Yes | Q13: Yes | R13: Yes | S13: Yes | T13: Yes | U13: Yes | V13: Yes | W13: [SYI_AC3_001_012]Limiting the charging voltage on the HV DC circuit.html | X13: 2 | Y13: 0 | Z13: 0 | AA13: 2 | AC13: TSR-CCU-011 | AO13: =EXACT(W13,AG13) | AP13: =EXACT(X13,AH13) | AQ13: =EXACT(Y13,AI13) | AR13: =EXACT(Z13,AJ13) | AS13: =EXACT(AA13,AK13)
A14: Yes | B14: Yes | C14: Yes | D14: Yes | E14: Yes | F14: Yes | G14: Yes | H14: Yes | I14: Yes | J14: Yes | K14: Yes | L14: Yes | M14: Yes | N14: Yes | O14: Yes | P14: Yes | Q14: Yes | R14: Yes | S14: Yes | T14: Yes | U14: Yes | V14: Yes | W14: [SYI_AC3_002_001]HVDC voltage measurement plausibility check.html | X14: 3 | Y14: 0 | Z14: 0 | AA14: 3 | AC14: TSR-CCU-073 | AG14: [SYI_AC3_002_001]HVDC voltage measurement plausibility check.html | AH14: 3 | AI14: 0 | AJ14: 0 | AK14: 3 | AO14: =EXACT(W14,AG14) | AP14: =EXACT(X14,AH14) | AQ14: =EXACT(Y14,AI14) | AR14: =EXACT(Z14,AJ14) | AS14: =EXACT(AA14,AK14) | AT14: 0000BA6C_009_030_063 | AU14: 0000BA78_009_030_061
A15: Yes | B15: Yes | C15: Yes | D15: Yes | E15: Yes | F15: Yes | G15: Yes | H15: Yes | I15: Yes | J15: Yes | K15: Yes | L15: Yes | M15: Yes | N15: Yes | O15: Yes | P15: Yes | Q15: Yes | R15: Yes | S15: Yes | T15: Yes | U15: Yes | V15: Yes | W15: [SYI_AC3_002_002]HVDC voltage measurement plausibility check.html | X15: 7 | Y15: 0 | Z15: 0 | AA15: 7 | AC15: TSR-CCU-074 | AG15: [SYI_AC3_002_002]HVDC voltage measurement plausibility check.html | AH15: 7 | AI15: 0 | AJ15: 0 | AK15: 7 | AO15: =EXACT(W15,AG15) | AP15: =EXACT(X15,AH15) | AQ15: =EXACT(Y15,AI15) | AR15: =EXACT(Z15,AJ15) | AS15: =EXACT(AA15,AK15) | AT15: 0000BA6C_009_030_063 | AU15: 0000BA78_009_030_061
A16: Yes | B16: Yes | C16: Yes | D16: Yes | E16: Yes | F16: Yes | G16: Yes | H16: Yes | I16: Yes | J16: Yes | K16: Yes | L16: Yes | M16: Yes | N16: Yes | O16: Yes | P16: Yes | Q16: Yes | R16: Yes | S16: Yes | T16: Yes | U16: Yes | V16: Yes | W16: [SYI_AC3_002_003]HVDC voltage measurement plausibility check.html | X16: 2 | Y16: 0 | Z16: 0 | AA16: 2 | AC16: TSR-CCU-015 | AG16: [SYI_AC3_002_003]HVDC voltage measurement plausibility check.html | AH16: 1 | AI16: 1 | AJ16: 4 | AK16: 2 | AO16: =EXACT(W16,AG16) | AP16: =EXACT(X16,AH16) | AQ16: =EXACT(Y16,AI16) | AR16: =EXACT(Z16,AJ16) | AS16: =EXACT(AA16,AK16) | AT16: 0000BA6C_009_030_063 | AU16: 0000BA78_009_030_061
A17: Yes | B17: Yes | C17: Yes | D17: Yes | E17: Yes | F17: Yes | G17: Yes | H17: Yes | I17: Yes | J17: Yes | K17: Yes | L17: Yes | M17: Yes | N17: Yes | O17: Yes | P17: Yes | Q17: Yes | R17: Yes | S17: Yes | T17: Yes | U17: Yes | V17: Yes | W17: [SYI_AC3_002_005]HVDC voltage measurement plausibility check.html | X17: 2 | Y17: 0 | Z17: 0 | AA17: 2 | AC17: TSR-CCU-028 | AG17: [SYI_AC3_002_005]HVDC voltage measurement plausibility check.html | AH17: 2 | AI17: 0 | AJ17: 0 | AK17: 2 | AO17: =EXACT(W17,AG17) | AP17: =EXACT(X17,AH17) | AQ17: =EXACT(Y17,AI17) | AR17: =EXACT(Z17,AJ17) | AS17: =EXACT(AA17,AK17) | AT17: 0000BA6C_009_030_063 | AU17: 0000BA78_009_030_061
A18: Yes | B18: Yes | C18: Yes | D18: Yes | E18: Yes | F18: Yes | G18: Yes | H18: Yes | I18: Yes | J18: Yes | K18: Yes | L18: Yes | M18: Yes | N18: Yes | O18: Yes | P18: Yes | Q18: Yes | R18: Yes | S18: Yes | T18: Yes | U18: Yes | V18: Yes | W18: [SYI_AC3_002_006]HVDC voltage measurement plausibility check.html | X18: 2 | Y18: 0 | Z18: 0 | AA18: 2 | AC18: TSR-CCU-029 | AG18: [SYI_AC3_002_006]HVDC voltage measurement plausibility check.html | AH18: 2 | AI18: 0 | AJ18: 0 | AK18: 2 | AO18: =EXACT(W18,AG18) | AP18: =EXACT(X18,AH18) | AQ18: =EXACT(Y18,AI18) | AR18: =EXACT(Z18,AJ18) | AS18: =EXACT(AA18,AK18) | AT18: 0000BA6C_009_030_063 | AU18: 0000BA78_009_030_061
A19: Yes | B19: Yes | C19: Yes | D19: Yes | E19: Yes | F19: Yes | G19: Yes | H19: Yes | I19: Yes | J19: Yes | K19: Yes | L19: Yes | M19: Yes | N19: Yes | O19: Yes | P19: Yes | Q19: Yes | R19: Yes | S19: Yes | T19: Yes | U19: Yes | V19: Yes | W19: [SYI_AC3_002_008]HVDC voltage measurement plausibility check.html | X19: 2 | Y19: 0 | Z19: 0 | AA19: 2 | AC19: TSR-CCU-001 | AG19: [SYI_AC3_002_008]HVDC voltage measurement plausibility check.html | AH19: 2 | AI19: 0 | AJ19: 0 | AK19: 2 | AO19: =EXACT(W19,AG19) | AP19: =EXACT(X19,AH19) | AQ19: =EXACT(Y19,AI19) | AR19: =EXACT(Z19,AJ19) | AS19: =EXACT(AA19,AK19) | AT19: 0000BA6C_009_030_063 | AU19: 0000BA78_009_030_061
A20: Yes | B20: Yes | C20: Yes | D20: Yes | E20: Yes | F20: Yes | G20: Yes | H20: Yes | I20: Yes | J20: Yes | K20: Yes | L20: Yes | M20: Yes | N20: Yes | O20: Yes | P20: Yes | Q20: Yes | R20: Yes | S20: Yes | T20: Yes | U20: Yes | V20: Yes | W20: [SYI_AC3_002_009]HVDC voltage measurement plausibility check.html | X20: 2 | Y20: 0 | Z20: 0 | AA20: 2 | AC20: TSR-CCU-003 | AG20: [SYI_AC3_002_009]HVDC voltage measurement plausibility check.html | AH20: 2 | AI20: 0 | AJ20: 0 | AK20: 2 | AO20: =EXACT(W20,AG20) | AP20: =EXACT(X20,AH20) | AQ20: =EXACT(Y20,AI20) | AR20: =EXACT(Z20,AJ20) | AS20: =EXACT(AA20,AK20) | AT20: 0000BA6C_009_030_063 | AU20: 0000BA78_009_030_061
A21: Yes | B21: Yes | C21: Yes | D21: Yes | E21: Yes | F21: Yes | G21: Yes | H21: Yes | I21: Yes | J21: Yes | K21: Yes | L21: Yes | M21: Yes | N21: Yes | O21: Yes | P21: Yes | Q21: Yes | R21: Yes | S21: Yes | T21: Yes | U21: Yes | V21: Yes | W21: [SYI_AC3_002_010]HVDC voltage measurement plausibility check.html | X21: 2 | Y21: 0 | Z21: 0 | AA21: 2 | AC21: TSR-CCU-075 | AG21: [SYI_AC3_002_010]HVDC voltage measurement plausibility check.html | AH21: 2 | AI21: 0 | AJ21: 0 | AK21: 2 | AO21: =EXACT(W21,AG21) | AP21: =EXACT(X21,AH21) | AQ21: =EXACT(Y21,AI21) | AR21: =EXACT(Z21,AJ21) | AS21: =EXACT(AA21,AK21) | AT21: 0000BA6C_009_030_063 | AU21: 0000BA78_009_030_061
A22: Yes | B22: Yes | C22: Yes | D22: Yes | E22: Yes | F22: Yes | G22: Yes | H22: Yes | I22: Yes | J22: Yes | K22: Yes | L22: Yes | M22: Yes | N22: Yes | O22: Yes | P22: Yes | Q22: Yes | R22: Yes | S22: Yes | T22: Yes | U22: Yes | V22: Yes | W22: [SYI_AC3_002_011]HVDC voltage measurement plausibility check.html | X22: 6 | Y22: 0 | Z22: 0 | AA22: 6 | AC22: TSR-CCU-103 | AG22: [SYI_AC3_002_011]HVDC voltage measurement plausibility check.html | AH22: 6 | AI22: 0 | AJ22: 0 | AK22: 6 | AO22: =EXACT(W22,AG22) | AP22: =EXACT(X22,AH22) | AQ22: =EXACT(Y22,AI22) | AR22: =EXACT(Z22,AJ22) | AS22: =EXACT(AA22,AK22) | AT22: 0000BA6C_009_030_063 | AU22: 0000BA78_009_030_061
E23: Yes | F23: Yes | G23: Yes | H23: Yes | I23: Yes | J23: Yes | K23: Yes | L23: Yes | M23: Yes | N23: Yes | O23: Yes | P23: Yes | Q23: Yes | R23: Yes | S23: Yes | T23: Yes | U23: Yes | V23: Yes | W23: [SYI_AC3_002_011]HVDC voltage measurement plausibility check_HW3.0.html | X23: 6 | Y23: 0 | Z23: 0 | AA23: 6 | AC23: TSR-CCU-103 | AE23: This test case is created specifically for HWSOP3.0 Testing refer to Task #267871 | AO23: =EXACT(W23,AG23) | AP23: =EXACT(X23,AH23) | AQ23: =EXACT(Y23,AI23) | AR23: =EXACT(Z23,AJ23) | AS23: =EXACT(AA23,AK23)
A24: No | B24: No | C24: No | D24: No | E24: No | F24: No | G24: No | H24: No | I24: No | J24: No | K24: No | L24: No | M24: No | N24: No | O24: No | P24: No | Q24: No | R24: No | S24: No | T24: No | U24: No | V24: No | W24: [SYI_AC3_004_001]HVDC overvoltage detection.html | X24: 2 | Y24: 0 | Z24: 0 | AA24: 2 | AC24: TSR-CCU-475 | AD24: Obsolete | AE24: Refer to ENG10 (Traceability matrix sheet ) | AO24: =EXACT(W24,AG24) | AP24: =EXACT(X24,AH24) | AQ24: =EXACT(Y24,AI24) | AR24: =EXACT(Z24,AJ24) | AS24: =EXACT(AA24,AK24)
D25: Yes | E25: Yes | F25: Yes | G25: Yes | I25: Yes | O25: Yes | Q25: Yes | R25: Yes | S25: Yes | T25: Yes | U25: Yes | V25: Yes | W25: [SYI_AC3_003_001] | X25: 2 | Y25: 0 | Z25: 0 | AA25: 2 | AO25: =EXACT(W25,AG25) | AP25: =EXACT(X25,AH25) | AQ25: =EXACT(Y25,AI25) | AR25: =EXACT(Z25,AJ25) | AS25: =EXACT(AA25,AK25)
A26: Yes | B26: Yes | C26: Yes | D26: Yes | E26: Yes | F26: Yes | G26: Yes | H26: Yes | I26: Yes | J26: Yes | K26: Yes | L26: Yes | M26: Yes | N26: Yes | O26: Yes | P26: Yes | Q26: Yes | R26: Yes | S26: Yes | T26: Yes | U26: Yes | V26: Yes | W26: [SYI_AC3_004_002]HVDC overvoltage detection.html | X26: 2 | Y26: 0 | Z26: 0 | AA26: 2 | AC26: TSR-CCU-476 | AG26: [SYI_AC3_004_002]HVDC overvoltage detection.html | AH26: 2 | AI26: 0 | AJ26: 0 | AK26: 2 | AO26: =EXACT(W26,AG26) | AP26: =EXACT(X26,AH26) | AQ26: =EXACT(Y26,AI26) | AR26: =EXACT(Z26,AJ26) | AS26: =EXACT(AA26,AK26) | AT26: 0000BA6C_009_030_063 | AU26: 0000BA78_009_030_061
A27: Yes | B27: Yes | C27: Yes | D27: Yes | E27: Yes | F27: Yes | G27: Yes | H27: Yes | I27: Yes | J27: Yes | K27: Yes | L27: Yes | M27: Yes | N27: Yes | O27: Yes | P27: Yes | Q27: Yes | R27: Yes | S27: Yes | T27: Yes | U27: Yes | V27: Yes | W27: [SYI_AC3_004_003]HVDC overvoltage detection.html | X27: 2 | Y27: 0 | Z27: 0 | AA27: 2 | AC27: TSR-CCU-477 | AG27: [SYI_AC3_004_003]HVDC overvoltage detection.html | AH27: 2 | AI27: 0 | AJ27: 0 | AK27: 2 | AO27: =EXACT(W27,AG27) | AP27: =EXACT(X27,AH27) | AQ27: =EXACT(Y27,AI27) | AR27: =EXACT(Z27,AJ27) | AS27: =EXACT(AA27,AK27) | AT27: 0000BA6C_009_030_063 | AU27: 0000BA78_009_030_061
A28: Yes | B28: Yes | C28: Yes | D28: Yes | E28: Yes | F28: Yes | G28: Yes | H28: Yes | I28: Yes | J28: Yes | K28: Yes | L28: Yes | M28: Yes | N28: Yes | O28: Yes | P28: Yes | Q28: Yes | R28: Yes | S28: Yes | T28: Yes | U28: Yes | V28: Yes | W28: [SYI_AC3_004_004]HVDC overvoltage detection.html | X28: 2 | Y28: 0 | Z28: 0 | AA28: 2 | AC28: TSR-CCU-003 | AG28: [SYI_AC3_004_004]HVDC overvoltage detection.html | AH28: 2 | AI28: 0 | AJ28: 0 | AK28: 2 | AO28: =EXACT(W28,AG28) | AP28: =EXACT(X28,AH28) | AQ28: =EXACT(Y28,AI28) | AR28: =EXACT(Z28,AJ28) | AS28: =EXACT(AA28,AK28) | AT28: 0000BA6C_009_030_063 | AU28: 0000BA78_009_030_061
A29: Yes | B29: Yes | C29: Yes | D29: Yes | E29: Yes | F29: Yes | G29: Yes | H29: Yes | I29: Yes | J29: Yes | K29: Yes | L29: Yes | M29: Yes | N29: Yes | O29: Yes | P29: Yes | Q29: Yes | R29: Yes | S29: Yes | T29: Yes | U29: Yes | V29: Yes | W29: [SYI_AC3_004_005]HVDC overvoltage detection.html | X29: 2 | Y29: 0 | Z29: 0 | AA29: 2 | AC29: TSR-CCU-478 | AG29: [SYI_AC3_004_005]HVDC overvoltage detection.html | AH29: 2 | AI29: 0 | AJ29: 0 | AK29: 2 | AO29: =EXACT(W29,AG29) | AP29: =EXACT(X29,AH29) | AQ29: =EXACT(Y29,AI29) | AR29: =EXACT(Z29,AJ29) | AS29: =EXACT(AA29,AK29) | AT29: 0000BA6C_009_030_063 | AU29: 0000BA78_009_030_061
A30: Yes | B30: Yes | C30: Yes | D30: Yes | E30: Yes | F30: Yes | G30: Yes | H30: Yes | I30: Yes | J30: Yes | K30: Yes | L30: Yes | M30: Yes | N30: Yes | O30: Yes | P30: Yes | Q30: Yes | R30: Yes | S30: Yes | T30: Yes | U30: Yes | V30: Yes | W30: [SYI_AC3_004_006]HVDC overvoltage detection.html | X30: 2 | Y30: 0 | Z30: 0 | AA30: 2 | AC30: TSR-CCU-479 | AG30: [SYI_AC3_004_006]HVDC overvoltage detection.html | AH30: 2 | AI30: 0 | AJ30: 0 | AK30: 2 | AO30: =EXACT(W30,AG30) | AP30: =EXACT(X30,AH30) | AQ30: =EXACT(Y30,AI30) | AR30: =EXACT(Z30,AJ30) | AS30: =EXACT(AA30,AK30) | AT30: 0000BA6C_009_030_063 | AU30: 0000BA78_009_030_061
A31: Yes | B31: Yes | C31: Yes | D31: Yes | E31: Yes | F31: Yes | G31: Yes | H31: Yes | I31: Yes | J31: Yes | K31: Yes | L31: Yes | M31: Yes | N31: Yes | O31: Yes | P31: Yes | Q31: Yes | R31: Yes | S31: Yes | T31: Yes | U31: Yes | V31: Yes | W31: [SYI_AC3_004_007]HVDC overvoltage detection.html | X31: 6 | Y31: 0 | Z31: 0 | AA31: 6 | AC31: TSR-CCU-710 | AG31: [SYI_AC3_004_007]HVDC overvoltage detection.html | AH31: 6 | AI31: 0 | AJ31: 0 | AK31: 6 | AO31: =EXACT(W31,AG31) | AP31: =EXACT(X31,AH31) | AQ31: =EXACT(Y31,AI31) | AR31: =EXACT(Z31,AJ31) | AS31: =EXACT(AA31,AK31) | AT31: 0000BA6C_009_030_063 | AU31: 0000BA78_009_030_061
A32: Yes | B32: Yes | C32: Yes | D32: Yes | E32: Yes | F32: Yes | G32: Yes | H32: Yes | I32: Yes | J32: Yes | K32: Yes | L32: Yes | M32: Yes | N32: Yes | O32: Yes | P32: Yes | Q32: Yes | R32: Yes | S32: Yes | T32: Yes | U32: Yes | V32: Yes | W32: [SYI_AC4_001_001]Contact protection for AC charging.html | X32: 3 | Y32: 0 | Z32: 0 | AA32: 3 | AC32: TSR-CCU-057 | AG32: [SYI_AC4_001_001]Contact protection for AC charging.html | AH32: 3 | AI32: 0 | AJ32: 0 | AK32: 3 | AO32: =EXACT(W32,AG32) | AP32: =EXACT(X32,AH32) | AQ32: =EXACT(Y32,AI32) | AR32: =EXACT(Z32,AJ32) | AS32: =EXACT(AA32,AK32) | AT32: 0000BA6C_009_030_063 | AU32: 0000BA78_009_030_061
A33: Yes | B33: Yes | C33: Yes | D33: Yes | E33: Yes | F33: Yes | G33: Yes | H33: Yes | I33: Yes | J33: Yes | K33: Yes | L33: Yes | M33: Yes | N33: Yes | O33: Yes | P33: Yes | Q33: Yes | R33: Yes | S33: Yes | T33: Yes | U33: Yes | V33: Yes | W33: [SYI_AC4_001_003]Contact protection for AC charging.html | X33: 3 | Y33: 0 | Z33: 0 | AA33: 3 | AC33: TSR-CCU-058 | AG33: [SYI_AC4_001_003]Contact protection for AC charging.html | AH33: 1 | AI33: 2 | AJ33: 0 | AK33: 3 | AO33: =EXACT(W33,AG33) | AP33: =EXACT(X33,AH33) | AQ33: =EXACT(Y33,AI33) | AR33: =EXACT(Z33,AJ33) | AS33: =EXACT(AA33,AK33) | AT33: 0000BA6C_009_030_063 | AU33: 0000BA78_009_030_061
A34: Yes | B34: Yes | C34: Yes | D34: Yes | E34: Yes | F34: Yes | G34: Yes | H34: Yes | I34: Yes | J34: Yes | K34: Yes | L34: Yes | M34: Yes | N34: Yes | O34: Yes | P34: Yes | Q34: Yes | R34: Yes | S34: Yes | T34: Yes | U34: Yes | V34: Yes | W34: [SYI_AC4_002_001]AC voltage measurement plausibility check.html | X34: 3 | Y34: 0 | Z34: 0 | AA34: 3 | AC34: TSR-CCU-076 | AG34: [SYI_AC4_002_001]AC voltage measurement plausibility check.html | AH34: 3 | AI34: 0 | AJ34: 0 | AK34: 3 | AO34: =EXACT(W34,AG34) | AP34: =EXACT(X34,AH34) | AQ34: =EXACT(Y34,AI34) | AR34: =EXACT(Z34,AJ34) | AS34: =EXACT(AA34,AK34) | AT34: 0000BA6C_009_030_063 | AU34: 0000BA78_009_030_061
A35: Yes | B35: Yes | C35: Yes | D35: Yes | E35: Yes | F35: Yes | G35: Yes | H35: Yes | I35: Yes | J35: Yes | K35: Yes | L35: Yes | M35: Yes | N35: Yes | O35: Yes | P35: Yes | Q35: Yes | R35: Yes | S35: Yes | T35: Yes | U35: Yes | V35: Yes | W35: [SYI_AC4_002_002]AC voltage measurement plausibility check.html | X35: 9 | Y35: 0 | Z35: 0 | AA35: 9 | AC35: TSR-CCU-077 | AG35: [SYI_AC4_002_002]AC voltage measurement plausibility check.html | AH35: 9 | AI35: 0 | AJ35: 9 | AK35: 9 | AO35: =EXACT(W35,AG35) | AP35: =EXACT(X35,AH35) | AQ35: =EXACT(Y35,AI35) | AR35: =EXACT(Z35,AJ35) | AS35: =EXACT(AA35,AK35) | AT35: 0000BA6C_009_030_063 | AU35: 0000BA78_009_030_061
A36: No | B36: No | C36: No | D36: No | E36: No | F36: No | G36: No | H36: No | I36: No | J36: No | K36: No | L36: No | M36: No | N36: No | O36: No | P36: No | Q36: No | R36: No | S36: No | T36: No | U36: No | V36: No | W36: [SYI_AC4_002_003]AC voltage measurement plausibility check.html | X36: 6 | Y36: 0 | Z36: 0 | AA36: 6 | AC36: TSR-CCU-079 | AD36: Obsolete | AE36: Refer to ENG 08 SWQT_050_001_005 (Traceability matrix sheet ) | AO36: =EXACT(W36,AG36) | AP36: =EXACT(X36,AH36) | AQ36: =EXACT(Y36,AI36) | AR36: =EXACT(Z36,AJ36) | AS36: =EXACT(AA36,AK36)
A37: Yes | B37: Yes | C37: Yes | D37: Yes | E37: Yes | F37: Yes | G37: Yes | H37: Yes | I37: Yes | J37: Yes | K37: Yes | L37: Yes | M37: Yes | N37: Yes | O37: Yes | P37: Yes | Q37: Yes | R37: Yes | S37: Yes | T37: Yes | U37: Yes | V37: Yes | W37: [SYI_AC4_002_004]AC voltage measurement plausibility check.html | X37: 3 | Y37: 0 | Z37: 0 | AA37: 3 | AC37: TSR-CCU-089 | AG37: [SYI_AC4_002_004]AC voltage measurement plausibility check.html | AH37: 3 | AI37: 0 | AJ37: 3 | AK37: 3 | AO37: =EXACT(W37,AG37) | AP37: =EXACT(X37,AH37) | AQ37: =EXACT(Y37,AI37) | AR37: =EXACT(Z37,AJ37) | AS37: =EXACT(AA37,AK37) | AT37: 0000BA6C_009_030_063 | AU37: 0000BA78_009_030_061
A38: Yes | B38: Yes | C38: Yes | D38: Yes | E38: Yes | F38: Yes | G38: Yes | H38: Yes | I38: Yes | J38: Yes | K38: Yes | L38: Yes | M38: Yes | N38: Yes | O38: Yes | P38: Yes | Q38: Yes | R38: Yes | S38: Yes | T38: Yes | U38: Yes | V38: Yes | W38: [SYI_AC4_003_001]AC passive discharge circuit failure detection.html | X38: 3 | Y38: 0 | Z38: 0 | AA38: 3 | AC38: TSR-CCU-080 | AO38: =EXACT(W38,AG38) | AP38: =EXACT(X38,AH38) | AQ38: =EXACT(Y38,AI38) | AR38: =EXACT(Z38,AJ38) | AS38: =EXACT(AA38,AK38)
A39: Yes | B39: Yes | C39: Yes | D39: Yes | E39: Yes | F39: Yes | G39: Yes | H39: Yes | I39: Yes | J39: Yes | K39: Yes | L39: Yes | M39: Yes | N39: Yes | O39: Yes | P39: Yes | Q39: Yes | R39: Yes | S39: Yes | T39: Yes | U39: Yes | V39: Yes | W39: [SYI_AC4_003_002]AC passive discharge circuit failure detection.html | X39: 3 | Y39: 0 | Z39: 0 | AA39: 3 | AC39: TSR-CCU-081 | AO39: =EXACT(W39,AG39) | AP39: =EXACT(X39,AH39) | AQ39: =EXACT(Y39,AI39) | AR39: =EXACT(Z39,AJ39) | AS39: =EXACT(AA39,AK39)
A40: Yes | B40: Yes | C40: Yes | D40: Yes | E40: Yes | F40: Yes | G40: Yes | H40: Yes | I40: Yes | J40: Yes | K40: Yes | L40: Yes | M40: Yes | N40: Yes | O40: Yes | P40: Yes | Q40: Yes | R40: Yes | S40: Yes | T40: Yes | U40: Yes | V40: Yes | W40: [SYI_AC4_003_003]AC passive discharge circuit failure detection.html | X40: 3 | Y40: 0 | Z40: 0 | AA40: 3 | AC40: TSR-CCU-085 | AO40: =EXACT(W40,AG40) | AP40: =EXACT(X40,AH40) | AQ40: =EXACT(Y40,AI40) | AR40: =EXACT(Z40,AJ40) | AS40: =EXACT(AA40,AK40)
...

Sheet FuSa_NACS
A1: SP18 | J1: SP21 | T1: SP21P | U1: Test Topic | V1: HW Functionality | W1: Reference | AW1: L2 Release
A2: SOP2207 | B2: SOP2211 | C2: SOP2307 | D2: SOP2407 | E2: SOP2503 | F2: SOP2507 | G2: SOP2603 | H2: SOP2311 | I2: SOP2403 | J2: SOP2211 | K2: SOP2303 | L2: SOP2307 | M2: SOP2407 | N2: SOP2311 | O2: SOP2403 | P2: SOP2503 | Q2: SOP2507 | R2: SOP2511 | S2: SOP2603 | T2: SOP2607 | W2: Test Case | X2: Pass | Y2: Fail | Z2: OtherFail | AA2: Total | AB2: Time | AC2: SYR/KLH ID | AD2: Status | AE2: Comment | AG2: Test Case | AH2: Pass | AI2: Fail | AJ2: OtherFail | AK2: Total | AL2: Time | AM2: Status | AN2: Comment | AO2: TC | AP2: Pass | AQ2: Fail | AR2: OtherFail | AS2: Total
D3: No | E3: No | F3: No | G3: No | H3: No | I3: No | M3: No | O3: No | P3: No | Q3: No | R3: Yes | S3: Yes | T3: Yes | U3: Fire Protection | W3: [SYI_FP40_001_001].html | X3: 1 | Y3: 0 | Z3: 0 | AA3: 1 | AB3: 0.0006712963 | AC3: TSR-CCU-NACS-951 'TSR-CCU-NACS-950 | AO3: =EXACT(W3,AG3) | AP3: =EXACT(X3,AH3) | AQ3: =EXACT(Y3,AI3) | AR3: =EXACT(Z3,AJ3) | AS3: =EXACT(AA3,AK3)
D4: No | E4: No | F4: No | G4: No | H4: No | I4: No | M4: No | O4: No | P4: No | Q4: No | R4: No | S4: No | T4: No | U4: Fire Protection | W4: [SYI_FP40_001_002].html | X4: 1 | Y4: 0 | Z4: 0 | AA4: 1 | AB4: 0.00081018519 | AC4: TSR-CCU-NACS-952 | AD4: Obsolete | AO4: =EXACT(W4,AG4) | AP4: =EXACT(X4,AH4) | AQ4: =EXACT(Y4,AI4) | AR4: =EXACT(Z4,AJ4) | AS4: =EXACT(AA4,AK4)
D5: No | E5: No | F5: No | G5: No | H5: No | I5: No | M5: No | O5: No | P5: No | Q5: No | R5: No | S5: No | T5: No | U5: Fire Protection | W5: [SYI_FP40_001_003].html | X5: 1 | Y5: 0 | Z5: 0 | AA5: 1 | AB5: 0.00055555556 | AC5: TSR-CCU-NACS-952,TSR-CCU-NACS-953,TSR-CCU-NACS-975 | AD5: Obsolete | AO5: =EXACT(W5,AG5) | AP5: =EXACT(X5,AH5) | AQ5: =EXACT(Y5,AI5) | AR5: =EXACT(Z5,AJ5) | AS5: =EXACT(AA5,AK5)
D6: No | E6: No | F6: No | G6: No | H6: No | I6: No | M6: No | O6: No | P6: No | Q6: No | R6: No | S6: No | T6: No | U6: Fire Protection | W6: [SYI_FP40_001_004].html | X6: 1 | Y6: 0 | Z6: 0 | AA6: 1 | AB6: 0.00055555556 | AC6: TSR-CCU-NACS-952 TSR-CCU-NACS-953 TSR-CCU-NACS-975 | AD6: Obsolete | AO6: =EXACT(W6,AG6) | AP6: =EXACT(X6,AH6) | AQ6: =EXACT(Y6,AI6) | AR6: =EXACT(Z6,AJ6) | AS6: =EXACT(AA6,AK6)
D7: No | E7: No | F7: No | G7: No | H7: No | I7: No | M7: No | O7: No | P7: No | Q7: No | R7: No | S7: No | T7: No | U7: Fire Protection | W7: [SYI_FP40_001_005].html | X7: 1 | Y7: 0 | Z7: 0 | AA7: 1 | AB7: 0.00055555556 | AC7: TSR-CCU-NACS-952 TSR-CCU-NACS-953 TSR-CCU-NACS-975 | AD7: Obsolete | AO7: =EXACT(W7,AG7) | AP7: =EXACT(X7,AH7) | AQ7: =EXACT(Y7,AI7) | AR7: =EXACT(Z7,AJ7) | AS7: =EXACT(AA7,AK7)
D8: No | E8: No | F8: No | G8: No | H8: No | I8: No | M8: No | O8: No | P8: No | Q8: No | R8: Yes | S8: Yes | T8: Yes | U8: Fire Protection | W8: [SYI_FP40_001_006].html | X8: 1 | Y8: 0 | Z8: 0 | AA8: 1 | AB8: 0.00054398148 | AC8: TSR-CCU-NACS-975 | AO8: =EXACT(W8,AG8) | AP8: =EXACT(X8,AH8) | AQ8: =EXACT(Y8,AI8) | AR8: =EXACT(Z8,AJ8) | AS8: =EXACT(AA8,AK8)
D9: No | E9: No | F9: No | G9: No | H9: No | I9: No | M9: No | O9: No | P9: No | Q9: No | R9: Yes | S9: Yes | T9: No | U9: Fire Protection | W9: [SYI_FP40_001_007].html | X9: 1 | Y9: 0 | Z9: 0 | AA9: 1 | AB9: 0.00052083333 | AC9: TSR-CCU-NACS-975 | AO9: =EXACT(W9,AG9) | AP9: =EXACT(X9,AH9) | AQ9: =EXACT(Y9,AI9) | AR9: =EXACT(Z9,AJ9) | AS9: =EXACT(AA9,AK9)
D10: No | E10: No | F10: No | G10: No | H10: No | I10: No | M10: No | O10: No | P10: No | Q10: No | R10: Yes | S10: Yes | T10: Yes | U10: Fire Protection | W10: [SYI_FP40_001_008].html | X10: 1 | Y10: 0 | Z10: 0 | AA10: 1 | AB10: 0.00054398148 | AC10: TSR-CCU-NACS-975 | AO10: =EXACT(W10,AG10) | AP10: =EXACT(X10,AH10) | AQ10: =EXACT(Y10,AI10) | AR10: =EXACT(Z10,AJ10) | AS10: =EXACT(AA10,AK10)
D11: No | E11: No | F11: No | G11: No | H11: No | I11: No | M11: No | O11: No | P11: No | Q11: No | R11: Yes | S11: Yes | T11: Yes | U11: Fire Protection | W11: [SYI_FP40_001_009].html | X11: 1 | Y11: 0 | Z11: 0 | AA11: 1 | AB11: 0.00054398148 | AC11: TSR-CCU-NACS-975 | AO11: =EXACT(W11,AG11) | AP11: =EXACT(X11,AH11) | AQ11: =EXACT(Y11,AI11) | AR11: =EXACT(Z11,AJ11) | AS11: =EXACT(AA11,AK11)
D12: No | E12: No | F12: No | G12: No | H12: No | I12: No | J12: No | K12: No | L12: No | M12: No | N12: No | O12: No | P12: No | Q12: No | R12: Yes | S12: Yes | T12: Yes | U12: Fire Protection | W12: [SYI_FP50_001_001] Verify default state of CP_Hot_Disconnect GPIO PIN 152.html | X12: 1 | Y12: 0 | Z12: 0 | AA12: 1 | AB12: 0.00078703704 | AC12: TSR-CCU-NACS-956 | AO12: =EXACT(W12,AG12) | AP12: =EXACT(X12,AH12) | AQ12: =EXACT(Y12,AI12) | AR12: =EXACT(Z12,AJ12) | AS12: =EXACT(AA12,AK12)
D13: No | E13: No | F13: No | G13: No | H13: No | I13: No | M13: No | O13: No | P13: No | Q13: No | R13: Yes | S13: Yes | T13: Yes | U13: Fire Protection | W13: [SYI_FP50_001_002] Verify CP_Hot_Disconnect is enabled (NACS HW && Correct SGBM_ID).html | X13: 1 | Y13: 0 | Z13: 0 | AA13: 1 | AB13: 0.00079861111 | AC13: TSR-CCU-NACS-954 TSR-CCU-NACS-955 TSR-CCU-NACS-973 TSR-CCU-NACS-976 | AO13: =EXACT(W13,AG13) | AP13: =EXACT(X13,AH13) | AQ13: =EXACT(Y13,AI13) | AR13: =EXACT(Z13,AJ13) | AS13: =EXACT(AA13,AK13)
D14: No | E14: No | F14: No | G14: No | H14: No | I14: No | M14: No | O14: No | P14: No | Q14: No | R14: Yes | S14: Yes | T14: Yes | U14: Fire Protection | W14: [SYI_FP50_001_003] Verify CP_Hot_Disconnect is enabled (NACS HW && Correct SGBM_ID).html | X14: 1 | Y14: 0 | Z14: 0 | AA14: 1 | AB14: 0.00047453704 | AC14: TSR-CCU-NACS-954 TSR-CCU-NACS-955 | AO14: =EXACT(W14,AG14) | AP14: =EXACT(X14,AH14) | AQ14: =EXACT(Y14,AI14) | AR14: =EXACT(Z14,AJ14) | AS14: =EXACT(AA14,AK14)
D15: No | E15: No | F15: No | G15: No | H15: No | I15: No | M15: No | O15: No | P15: No | Q15: No | R15: Yes | S15: Yes | T15: No | U15: Fire Protection | W15: [SYI_FP50_001_004] Verify CP_Hot_Disconnect is disabled (NACS HW && Correct SGBM_ID)_SP21.html | X15: 1 | Y15: 0 | Z15: 0 | AA15: 1 | AB15: 0.00076388889 | AC15: TSR-CCU-NACS-973 TSR-CCU-NACS-976 | AO15: =EXACT(W15,AG15) | AP15: =EXACT(X15,AH15) | AQ15: =EXACT(Y15,AI15) | AR15: =EXACT(Z15,AJ15) | AS15: =EXACT(AA15,AK15)
E16: No | F16: No | G16: No | H16: No | I16: No | M16: No | O16: No | P16: No | Q16: No | R16: No | S16: No | T16: Yes | U16: Fire Protection | W16: [SYI_FP50_001_004] Verify CP_Hot_Disconnect is disabled (NACS HW && Correct SGBM_ID)_SP21P.html | X16: 9 | Y16: 0 | Z16: 0 | AA16: 9 | AB16: 0.00076388889 | AC16: TSR-CCU-NACS-973 TSR-CCU-NACS-976 | AO16: =EXACT(W16,AG16) | AP16: =EXACT(X16,AH16) | AQ16: =EXACT(Y16,AI16) | AR16: =EXACT(Z16,AJ16) | AS16: =EXACT(AA16,AK16)
E17: No | F17: No | G17: No | H17: No | I17: No | M17: No | O17: No | P17: No | Q17: Yes | R17: Yes | S17: Yes | T17: No | U17: Fire Protection | W17: [SYI_FP50_001_005] Verify CP_Hot_Disconnect is disabled (Non-NACS HW)_SP21.html | X17: 1 | Y17: 0 | Z17: 0 | AA17: 1 | AB17: 0.00050925926 | AC17: TSR-CCU-NACS-973 TSR-CCU-NACS-976 | AO17: =EXACT(W17,AG17) | AP17: =EXACT(X17,AH17) | AQ17: =EXACT(Y17,AI17) | AR17: =EXACT(Z17,AJ17) | AS17: =EXACT(AA17,AK17) | AW17: YES
D18: No | E18: No | F18: No | G18: No | H18: No | I18: No | M18: No | O18: No | P18: No | Q18: No | R18: No | S18: No | T18: Yes | U18: Fire Protection | W18: [SYI_FP50_001_005] Verify CP_Hot_Disconnect is disabled (Non-NACS HW)_SP21P_HWEL008.html | X18: 10 | Y18: 0 | Z18: 0 | AA18: 10 | AB18: 0.00050925926 | AC18: TSR-CCU-NACS-973 TSR-CCU-NACS-976 | AO18: =EXACT(W18,AG18) | AP18: =EXACT(X18,AH18) | AQ18: =EXACT(Y18,AI18) | AR18: =EXACT(Z18,AJ18) | AS18: =EXACT(AA18,AK18) | AW18: YES
D19: No | E19: No | F19: No | G19: No | H19: No | I19: No | M19: No | O19: No | P19: No | Q19: No | R19: No | S19: No | T19: Yes | U19: Fire Protection | W19: [SYI_FP50_001_005] Verify CP_Hot_Disconnect is disabled (Non-NACS HW)_SP21P_HWEL108.html | X19: 10 | Y19: 0 | Z19: 0 | AA19: 10 | AB19: 0.00050925926 | AC19: TSR-CCU-NACS-973 TSR-CCU-NACS-976 | AO19: =EXACT(W19,AG19) | AP19: =EXACT(X19,AH19) | AQ19: =EXACT(Y19,AI19) | AR19: =EXACT(Z19,AJ19) | AS19: =EXACT(AA19,AK19) | AW19: YES
D20: No | E20: No | F20: No | G20: No | H20: No | I20: No | M20: No | O20: No | P20: No | Q20: No | R20: Yes | S20: Yes | T20: Yes | U20: Fire Protection | W20: [SYI_FP50_001_006] Verify 0x031B96 is suppressed when CP_Hot_Disconnect_Request is open.html | X20: 1 | Y20: 0 | Z20: 0 | AA20: 1 | AB20: 0.00046296296 | AC20: TSR-CCU-NACS-970 | AO20: =EXACT(W20,AG20) | AP20: =EXACT(X20,AH20) | AQ20: =EXACT(Y20,AI20) | AR20: =EXACT(Z20,AJ20) | AS20: =EXACT(AA20,AK20)
